Workbook

Sheet Contents
D4: Statutory homelessness: Detailed local authority-level tables
D5: April 2024 to March 2025
D6: England
D7: 45988
C9: Accredited Official Statistics
C10: Households initially assessed as threatened with homelessness (owed prevention duty) or homeless (owed relief duty)1
C11: Table No. | D11: Subject | L11: Geography
C12: A1 | D12: Initial assessment of homelessness circumstances and needs | L12: Local authority
C13: A2P | D13: Households owed a prevention duty by reason for loss, or threat of loss, of last settled home | L13: Local authority
C14: A2R | D14: Households owed a relief duty by reason for loss, or threat of loss, of last settled home | L14: Local authority
C15: A3 | D15: Support needs of household | L15: Local authority
C16: A4P | D16: Households owed a prevention duty by accommodation at time of application | L16: Local authority
C17: A4R | D17: Households owed a relief duty by accommodation at time of application | L17: Local authority
C18: A5P | D18: Household composition (threatened with homelessness) | L18: Local authority
C19: A5R | D19: Household composition (homeless) | L19: Local authority
C20: A6 | D20: Age of main applicant | L20: Local authority
C21: A7 | D21: Referrals, including under the Duty to Refer | L21: Local authority
C22: A8 | D22: Ethnicity of main applicant | L22: Local authority
... C27: A13 | D27: Gender identity of main applicant | L27: local authority
C29: Households whose prevention duty ended2
C30: P1 | D30: Reason for end of prevention duty | L30: Local authority
C31: P2 | D31: Accommodation secured at prevention duty end | L31: Local authority
C32: P3 | D32: Main prevention activity to secure accommodation | L32: Local authority
C33: P4 | D33: Location of alternative accommodation secured | L33: Local authority
C34: P5 | D34: Household composition of those secured accommodation | L34: Local authority
C36: Households whose relief duty ended2
C37: R1 | D37: Reason for end of relief duty | L37: Local authority
C38: R2 | D38: Accommodation secured at relief duty end | L38: Local authority
C39: R3 | D39: Main relief activity to secure accommodation | L39: Local authority
C40: R4 | D40: Location of accommodation secured | L40: Local authority
C41: R5 | D41: Household composition of those secured accommodation | L41: Local authority
C43: Households assessed, following relief duty end, as unintentionally homeless and priority need (owed main duty)3
C44: MD1 | D44: Decision on duty owed at end of relief duty | L44: Local authority
C45: MD3 | D45: Priority need of households owed main duty | L45: Local authority
C47: Households whose main duty ended3
C48: MD2 | D48: Reason for end of main duty | L48: Local authority
B51: 1 | C51: These tables include information on new prevention and relief duties owed. Prevention duties include any activities aimed at preventing a household threatened with homelessness within 56 days from becoming homeless. Relief duties are owed to households that are already homeless and require help to secure settled accommodation. They are not comparable with the homelessness decisions or prevention/relief activity reported prior to May 2018. This is because amendments to legislation, as introduced by the 2017 HRA, have introduced new duties that mean more people will be eligible for assistance out of homelessness from local authorities.
C55: 18 local authorities had missing data on initial assessment information. National and regional totals were weighted based on previous trends for these authorities. They are highlighted and referenced in the data tables, and are estimated to comprise of 6.9% of total assessments in England. There may be seasonal trends in this data, which is not currently adjusted.
B56: 2 | C56: 15 out of 296 local authorities had missing data on prevention and relief outcomes. Therefore the corresponding regional totals were weighted to account for these. These are estimated to comprise of 4.6% of prevention outcomes and 6.4% of relief outcomes in England.
B58: 3 | C58: Main duty describes the duty a local authority has towards an applicant who is unintentionally homeless, eligible for assistance and has priority need. This definition has not been changed by the 2017 HRA. However, these households are now only owed a main duty if they did not secure accommodation in the prevention or relief stage.
...

Sheet LA_dropdown_(A1-A12)
C3: Initial assessments of statutory homelessness duties owed England, April 2024 to March 2025
C5: Select local authority by clicking on the box below and using the drop-down button below:
C6: York
C8: Number and % of households | G8: Number and % of households
B9: Total number of households assessed1,2 | C9: =INDEX('A1'!$B$2:$R$331,MATCH($C$6,'A1'!$B2:$B331,0),MATCH(B9,'A1'!B$2:R$2,0)) -> 810 | F9: Total households with support need(s) owed a duty | G9: =INDEX('A3'!$B$2:$AI$323,MATCH($C$6,'A3'!$B$2:$B$323,0),MATCH(F9,'A3'!$B$2:$AI$2,0)) -> 485 | H9: =IF(OR(G9="..",G9="-",$C$10=0),"",G9/$C$10) -> 0.60099133
B10: Total households assessed as owed a duty | C10: =INDEX('A1'!$B$2:$R$331,MATCH($C$6,'A1'!$B$2:$B$331,0),MATCH(B10,'A1'!B$2:R$2,0)) -> 807 | D10: =IF(OR(C10="..",C10="-",$C$9=0),"",C10/$C$9) -> 0.9962963 | F10: Total number of support needs for those owed a duty5 | G10: =INDEX('A3'!$B$2:$AI$323,MATCH($C$6,'A3'!$B$2:$B$323,0),MATCH(F10,'A3'!$B$2:$AI$2,0)) -> 830
B12: Households assessed and duty owed: | F12: Support needs of households owed a prevention or relief duty7:
B13: Threatened with homelessness - Prevention duty owed | C13: =INDEX('A1'!$B$2:$AG$321,MATCH($C$6,'A1'!$B$2:$B$321,0),MATCH(B13,'A1'!$B$2:$AG$2,0)) -> 529 | D13: =IF(OR(C13="..",C13="-",$C$9=0),"",C13/$C$9) -> 0.65308642 | F13: History of mental health problems | G13: =INDEX('A3'!$B$2:$AK$323,MATCH($C$6,'A3'!$B$2:$B$323,0),MATCH(F13,'A3'!$B$2:$AK$2,0)) -> 130 | H13: =IF(OR(G13="..",G13="-",$C$10=0),"",G13/$C$10) -> 0.16109046
B14: Of which: due to service of valid Section 21 Notice | C14: =INDEX('A1'!$B$2:$AG$321,MATCH($C$6,'A1'!$B$2:$B$321,0),MATCH(B14,'A1'!$B$2:$AG$2,0)) -> 118 | D14: =IF(OR(C14="..",C14="-",$C$9=0),"",C14/$C$9) -> 0.14567901 | F14: Physical ill health and disability | G14: =INDEX('A3'!$B$2:$AK$323,MATCH($C$6,'A3'!$B$2:$B$323,0),MATCH(F14,'A3'!$B$2:$AK$2,0)) -> 93 | H14: =IF(OR(G14="..",G14="-",$C$10=0),"",G14/$C$10) -> 0.11524164
B15: Homeless - Relief duty owed | C15: =INDEX('A1'!$B$2:$AG$321,MATCH($C$6,'A1'!$B$2:$B$321,0),MATCH(B15,'A1'!$B$2:$AG$2,0)) -> 278 | D15: =IF(OR(C15="..",C15="-",$C$9=0),"",C15/$C$9) -> 0.34320988 | F15: At risk of / has experienced domestic abuse | G15: =INDEX('A3'!$B$2:$AK$323,MATCH($C$6,'A3'!$B$2:$B$323,0),MATCH(F15,'A3'!$B$2:$AK$2,0)) -> 75 | H15: =IF(OR(G15="..",G15="-",$C$10=0),"",G15/$C$10) -> 0.092936803
B16: Not threatened with homelessness within 56 days - no duty owed | C16: =INDEX('A1'!$B$2:$AG$321,MATCH($C$6,'A1'!$B$2:$B$321,0),MATCH(B16,'A1'!$B$2:$AG$2,0)) -> 3 | D16: =IF(OR(C16="..",C16="-",$C$9=0),"",C16/$C$9) -> 0.0037037037 | F16: Offending history | G16: =INDEX('A3'!$B$2:$AK$323,MATCH($C$6,'A3'!$B$2:$B$323,0),MATCH(F16,'A3'!$B$2:$AK$2,0)) -> 73 | H16: =IF(OR(G16="..",G16="-",$C$10=0),"",G16/$C$10) -> 0.090458488
B17: Withdrew application before assessment - no duty owed | C17: =INDEX('A1'!$B$2:$AG$321,MATCH($C$6,'A1'!$B$2:$B$321,0),MATCH(B17,'A1'!$B$2:$AG$2,0)) -> 0 | D17: =IF(OR(C17="..",C17="-",$C$9=0),"",C17/$C$9) -> 0 | F17: History of repeat homelessness | G17: =INDEX('A3'!$B$2:$AK$323,MATCH($C$6,'A3'!$B$2:$B$323,0),MATCH(F17,'A3'!$B$2:$AK$2,0)) -> 54 | H17: =IF(OR(G17="..",G17="-",$C$10=0),"",G17/$C$10) -> 0.066914498
B18: Not eligible / no longer eligible - no duty owed | C18: =INDEX('A1'!$B$2:$AG$321,MATCH($C$6,'A1'!$B$2:$B$321,0),MATCH(B18,'A1'!$B$2:$AG$2,0)) -> 0 | D18: =IF(OR(C18="..",C18="-",$C$9=0),"",C18/$C$9) -> 0 | F18: Drug dependency needs | G18: =INDEX('A3'!$B$2:$AK$323,MATCH($C$6,'A3'!$B$2:$B$323,0),MATCH(F18,'A3'!$B$2:$AK$2,0)) -> 44 | H18: =IF(OR(G18="..",G18="-",$C$10=0),"",G18/$C$10) -> 0.054522924
F19: History of rough sleeping | G19: =INDEX('A3'!$B$2:$AK$323,MATCH($C$6,'A3'!$B$2:$B$323,0),MATCH(F19,'A3'!$B$2:$AK$2,0)) -> 22 | H19: =IF(OR(G19="..",G19="-",$C$10=0),"",G19/$C$10) -> 0.027261462
B20: Reason for loss of last settled home for households owed a prevention duty: | F20: Alcohol dependency needs | G20: =INDEX('A3'!$B$2:$AK$323,MATCH($C$6,'A3'!$B$2:$B$323,0),MATCH(F20,'A3'!$B$2:$AK$2,0)) -> 35 | H20: =IF(OR(G20="..",G20="-",$C$10=0),"",G20/$C$10) -> 0.043370508
B21: Family or friends no longer willing or able to accommodate | C21: =INDEX(A2P!$B$2:$BF$318, MATCH($C$6, A2P!$B$2:$B$318,0), MATCH(B21, A2P!$B$2:$BF$2, 0)) -> 153 | D21: =IF(OR(C21="..",C21="-",$C$13=0),"",C21/$C$13) -> 0.28922495 | F21: Learning disability | G21: =INDEX('A3'!$B$2:$AK$323,MATCH($C$6,'A3'!$B$2:$B$323,0),MATCH(F21,'A3'!$B$2:$AK$2,0)) -> 16 | H21: =IF(OR(G21="..",G21="-",$C$10=0),"",G21/$C$10) -> 0.019826518
B22: End of private rented tenancy - assured shorthold | C22: =INDEX(A2P!$B$2:$BF$318, MATCH($C$6, A2P!$B$2:$B$318,0), MATCH(B22, A2P!$B$2:$BF$2, 0)) -> 190 | D22: =IF(OR(C22="..",C22="-",$C$13=0),"",C22/$C$13) -> 0.35916824 | F22: Young person aged 18-25 years requiring support to manage independently | G22: =INDEX('A3'!$B$2:$AK$323,MATCH($C$6,'A3'!$B$2:$B$323,0),MATCH(F22,'A3'!$B$2:$AK$2,0)) -> 55 | H22: =IF(OR(G22="..",G22="-",$C$10=0),"",G22/$C$10) -> 0.068153656
B23: Domestic abuse | C23: =INDEX(A2P!$B$2:$BF$318, MATCH($C$6, A2P!$B$2:$B$318,0), MATCH(B23, A2P!$B$2:$BF$2, 0)) -> 30 | D23: =IF(OR(C23="..",C23="-",$C$13=0),"",C23/$C$13) -> 0.056710775 | F23: Access to education, employment or training | G23: =INDEX('A3'!$B$2:$AK$323,MATCH($C$6,'A3'!$B$2:$B$323,0),MATCH(F23,'A3'!$B$2:$AK$2,0)) -> 4 | H23: =IF(OR(G23="..",G23="-",$C$10=0),"",G23/$C$10) -> 0.0049566295
B24: Non-violent relationship breakdown with partner | C24: =INDEX(A2P!$B$2:$BF$318, MATCH($C$6, A2P!$B$2:$B$318,0), MATCH(B24, A2P!$B$2:$BF$2, 0)) -> 58 | D24: =IF(OR(C24="..",C24="-",$C$13=0),"",C24/$C$13) -> 0.10964083 | F24: At risk of / has experienced abuse (non-domestic abuse) | G24: =INDEX('A3'!$B$2:$AK$323,MATCH($C$6,'A3'!$B$2:$B$323,0),MATCH(F24,'A3'!$B$2:$AK$2,0)) -> 12 | H24: =IF(OR(G24="..",G24="-",$C$10=0),"",G24/$C$10) -> 0.014869888
B25: End of social rented tenancy | C25: =INDEX(A2P!$B$2:$BF$318, MATCH($C$6, A2P!$B$2:$B$318,0), MATCH(B25, A2P!$B$2:$BF$2, 0)) -> 10 | D25: =IF(OR(C25="..",C25="-",$C$13=0),"",C25/$C$13) -> 0.018903592 | F25: At risk of / has experienced sexual abuse / exploitation | G25: =INDEX('A3'!$B$2:$AK$323,MATCH($C$6,'A3'!$B$2:$B$323,0),MATCH(F25,'A3'!$B$2:$AK$2,0)) -> 7 | H25: =IF(OR(G25="..",G25="-",$C$10=0),"",G25/$C$10) -> 0.0086741016
B26: Eviction from supported housing | C26: =INDEX(A2P!$B$2:$BF$318, MATCH($C$6, A2P!$B$2:$B$318,0), MATCH(B26, A2P!$B$2:$BF$2, 0)) -> 7 | D26: =IF(OR(C26="..",C26="-",$C$13=0),"",C26/$C$13) -> 0.013232514 | F26: Old age | G26: =INDEX('A3'!$B$2:$AK$323,MATCH($C$6,'A3'!$B$2:$B$323,0),MATCH(F26,'A3'!$B$2:$AK$2,0)) -> 16 | H26: =IF(OR(G26="..",G26="-",$C$10=0),"",G26/$C$10) -> 0.019826518
B27: End of private rented tenancy - not assured shorthold | C27: =INDEX(A2P!$B$2:$BF$318, MATCH($C$6, A2P!$B$2:$B$318,0), MATCH(B27, A2P!$B$2:$BF$2, 0)) -> 10 | D27: =IF(OR(C27="..",C27="-",$C$13=0),"",C27/$C$13) -> 0.018903592 | F27: Care leaver aged 18-20 years | G27: =INDEX('A3'!$B$2:$AK$323,MATCH($C$6,'A3'!$B$2:$B$323,0),MATCH(F27,'A3'!$B$2:$AK$2,0)) -> 3 | H27: =IF(OR(G27="..",G27="-",$C$10=0),"",G27/$C$10) -> 0.0037174721
B28: Other violence or harrassment | C28: =INDEX(A2P!$B$2:$BF$318, MATCH($C$6, A2P!$B$2:$B$318,0), MATCH(B28, A2P!$B$2:$BF$2, 0)) -> 4 | D28: =IF(OR(C28="..",C28="-",$C$13=0),"",C28/$C$13) -> 0.0075614367 | F28: Care leaver aged 21-24 years | G28: =INDEX('A3'!$B$2:$AK$323,MATCH($C$6,'A3'!$B$2:$B$323,0),MATCH(F28,'A3'!$B$2:$AK$2,0)) -> 2 | H28: =IF(OR(G28="..",G28="-",$C$10=0),"",G28/$C$10) -> 0.0024783147
B29: Left institution with no accommodation available | C29: =INDEX(A2P!$B$2:$BF$318, MATCH($C$6, A2P!$B$2:$B$318,0), MATCH(B29, A2P!$B$2:$BF$2, 0)) -> 18 | D29: =IF(OR(C29="..",C29="-",$C$13=0),"",C29/$C$13) -> 0.034026465 | F29: Care leaver aged 25+ years | G29: =INDEX('A3'!$B$2:$AK$323,MATCH($C$6,'A3'!$B$2:$B$323,0),MATCH(F29,'A3'!$B$2:$AK$2,0)) -> 2 | H29: =IF(OR(G29="..",G29="-",$C$10=0),"",G29/$C$10) -> 0.0024783147
B30: Required to leave accommodation provided by Home Office as asylum support | C30: =INDEX(A2P!$B$2:$BF$318, MATCH($C$6, A2P!$B$2:$B$318,0), MATCH(B30, A2P!$B$2:$BF$2, 0)) -> 17 | D30: =IF(OR(C30="..",C30="-",$C$13=0),"",C30/$C$13) -> 0.032136106 | F30: Care leaver aged 21+ years (retired option) | G30: =INDEX('A3'!$B$2:$AK$323,MATCH($C$6,'A3'!$B$2:$B$323,0),MATCH(F30,'A3'!$B$2:$AK$2,0)) -> 1 | H30: =IF(OR(G30="..",G30="-",$C$10=0),"",G30/$C$10) -> 0.0012391574
B31: Home no longer suitable - disability / ill health | C31: =INDEX(A2P!$B$2:$BF$318, MATCH($C$6, A2P!$B$2:$B$318,0), MATCH(B31, A2P!$B$2:$BF$2, 0)) -> 1 | D31: =IF(OR(C31="..",C31="-",$C$13=0),"",C31/$C$13) -> 0.0018903592 | F31: Young person aged 16-17 years | G31: =INDEX('A3'!$B$2:$AK$323,MATCH($C$6,'A3'!$B$2:$B$323,0),MATCH(F31,'A3'!$B$2:$AK$2,0)) -> 13 | H31: =IF(OR(G31="..",G31="-",$C$10=0),"",G31/$C$10) -> 0.016109046
B32: Other reasons / not known6 | C32: =INDEX(A2P!$B$2:$BF$318, MATCH($C$6, A2P!$B$2:$B$318,0), MATCH(B32, A2P!$B$2:$BF$2, 0)) -> 29 | D32: =IF(OR(C32="..",C32="-",$C$13=0),"",C32/$C$13) -> 0.054820416 | F32: Young parent requiring support to manage independently | G32: =INDEX('A3'!$B$2:$AK$323,MATCH($C$6,'A3'!$B$2:$B$323,0),MATCH(F32,'A3'!$B$2:$AK$2,0)) -> 17 | H32: =IF(OR(G32="..",G32="-",$C$10=0),"",G32/$C$10) -> 0.021065675
F33: Former asylum seeker | G33: =INDEX('A3'!$B$2:$AK$323,MATCH($C$6,'A3'!$B$2:$B$323,0),MATCH(F33,'A3'!$B$2:$AK$2,0)) -> 23 | H33: =IF(OR(G33="..",G33="-",$C$10=0),"",G33/$C$10) -> 0.02850062
B34: Reason for loss of last settled home for households owed a relief duty: | F34: Served in HM Forces | G34: =INDEX('A3'!$B$2:$AK$323,MATCH($C$6,'A3'!$B$2:$B$323,0),MATCH(F34,'A3'!$B$2:$AK$2,0)) -> 3 | H34: =IF(OR(G34="..",G34="-",$C$10=0),"",G34/$C$10) -> 0.0037174721
B35: Family or friends no longer willing or able to accommodate | C35: =INDEX(A2R!$B$2:$BF$318, MATCH($C$6, A2R!$B$2:$B$318,0), MATCH(B35, A2R!$B$2:$BF$2, 0)) -> 117 | D35: =IF(OR(C35="..",C35="-",$C$15=0),"",C35/$C$15) -> 0.42086331 | F35: Victim of modern slavery | G35: =INDEX('A3'!$B$2:$AK$323,MATCH($C$6,'A3'!$B$2:$B$323,0),MATCH(F35,'A3'!$B$2:$AK$2,0)) -> 1 | H35: =IF(OR(G35="..",G35="-",$C$10=0),"",G35/$C$10) -> 0.0012391574
B36: End of private rented tenancy - assured shorthold | C36: =INDEX(A2R!$B$2:$BF$318, MATCH($C$6, A2R!$B$2:$B$318,0), MATCH(B36, A2R!$B$2:$BF$2, 0)) -> 16 | D36: =IF(OR(C36="..",C36="-",$C$15=0),"",C36/$C$15) -> 0.057553957 | F36: Difficulties budgeting | G36: =INDEX('A3'!$B$2:$AK$323,MATCH($C$6,'A3'!$B$2:$B$323,0),MATCH(F36,'A3'!$B$2:$AK$2,0)) -> 129 | H36: =IF(OR(G36="..",G36="-",$C$10=0),"",G36/$C$10) -> 0.1598513
B37: Domestic abuse | C37: =INDEX(A2R!$B$2:$BF$318, MATCH($C$6, A2R!$B$2:$B$318,0), MATCH(B37, A2R!$B$2:$BF$2, 0)) -> 43 | D37: =IF(OR(C37="..",C37="-",$C$15=0),"",C37/$C$15) -> 0.15467626
B38: Non-violent relationship breakdown with partner | C38: =INDEX(A2R!$B$2:$BF$318, MATCH($C$6, A2R!$B$2:$B$318,0), MATCH(B38, A2R!$B$2:$BF$2, 0)) -> 14 | D38: =IF(OR(C38="..",C38="-",$C$15=0),"",C38/$C$15) -> 0.050359712 | F38: Age of main applicants owed a prevention or relief duty7:
B39: End of social rented tenancy | C39: =INDEX(A2R!$B$2:$BF$318, MATCH($C$6, A2R!$B$2:$B$318,0), MATCH(B39, A2R!$B$2:$BF$2, 0)) -> 7 | D39: =IF(OR(C39="..",C39="-",$C$15=0),"",C39/$C$15) -> 0.025179856 | F39: 16-17 | G39: =INDEX('A6'!$B$2:$X$319,MATCH($C$6,'A6'!$B$2:$B$319,0),MATCH(F39,'A6'!$B$2:$X$2,0)) -> 10 | H39: =IF(OR(G39="..",G39="-",$C$10=0),"",G39/$C$10) -> 0.012391574
B40: Eviction from supported housing | C40: =INDEX(A2R!$B$2:$BF$318, MATCH($C$6, A2R!$B$2:$B$318,0), MATCH(B40, A2R!$B$2:$BF$2, 0)) -> 25 | D40: =IF(OR(C40="..",C40="-",$C$15=0),"",C40/$C$15) -> 0.089928058 | F40: 18-24 | G40: =INDEX('A6'!$B$2:$X$319,MATCH($C$6,'A6'!$B$2:$B$319,0),MATCH(F40,'A6'!$B$2:$X$2,0)) -> 155 | H40: =IF(OR(G40="..",G40="-",$C$10=0),"",G40/$C$10) -> 0.19206939
B41: End of private rented tenancy - not assured shorthold | C41: =INDEX(A2R!$B$2:$BF$318, MATCH($C$6, A2R!$B$2:$B$318,0), MATCH(B41, A2R!$B$2:$BF$2, 0)) -> 5 | D41: =IF(OR(C41="..",C41="-",$C$15=0),"",C41/$C$15) -> 0.017985612 | F41: 25-34 | G41: =INDEX('A6'!$B$2:$X$319,MATCH($C$6,'A6'!$B$2:$B$319,0),MATCH(F41,'A6'!$B$2:$X$2,0)) -> 209 | H41: =IF(OR(G41="..",G41="-",$C$10=0),"",G41/$C$10) -> 0.25898389
B42: Other violence or harrassment | C42: =INDEX(A2R!$B$2:$BF$318, MATCH($C$6, A2R!$B$2:$B$318,0), MATCH(B42, A2R!$B$2:$BF$2, 0)) -> 6 | D42: =IF(OR(C42="..",C42="-",$C$15=0),"",C42/$C$15) -> 0.021582734 | F42: 35-44 | G42: =INDEX('A6'!$B$2:$X$319,MATCH($C$6,'A6'!$B$2:$B$319,0),MATCH(F42,'A6'!$B$2:$X$2,0)) -> 204 | H42: =IF(OR(G42="..",G42="-",$C$10=0),"",G42/$C$10) -> 0.2527881
B43: Left institution with no accommodation available | C43: =INDEX(A2R!$B$2:$BF$318, MATCH($C$6, A2R!$B$2:$B$318,0), MATCH(B43, A2R!$B$2:$BF$2, 0)) -> 11 | D43: =IF(OR(C43="..",C43="-",$C$15=0),"",C43/$C$15) -> 0.039568345 | F43: 45-54 | G43: =INDEX('A6'!$B$2:$X$319,MATCH($C$6,'A6'!$B$2:$B$319,0),MATCH(F43,'A6'!$B$2:$X$2,0)) -> 119 | H43: =IF(OR(G43="..",G43="-",$C$10=0),"",G43/$C$10) -> 0.14745973
B44: Required to leave accommodation provided by Home Office as asylum support | C44: =INDEX(A2R!$B$2:$BF$318, MATCH($C$6, A2R!$B$2:$B$318,0), MATCH(B44, A2R!$B$2:$BF$2, 0)) -> 4 | D44: =IF(OR(C44="..",C44="-",$C$15=0),"",C44/$C$15) -> 0.014388489 | F44: 55-64 | G44: =INDEX('A6'!$B$2:$X$319,MATCH($C$6,'A6'!$B$2:$B$319,0),MATCH(F44,'A6'!$B$2:$X$2,0)) -> 71 | H44: =IF(OR(G44="..",G44="-",$C$10=0),"",G44/$C$10) -> 0.087980173
B45: Home no longer suitable - disability / ill health | C45: =INDEX(A2R!$B$2:$BF$318, MATCH($C$6, A2R!$B$2:$B$318,0), MATCH(B45, A2R!$B$2:$BF$2, 0)) -> 0 | D45: =IF(OR(C45="..",C45="-",$C$13=0),"",C45/$C$13) -> 0 | F45: 65-74 | G45: =INDEX('A6'!$B$2:$X$319,MATCH($C$6,'A6'!$B$2:$B$319,0),MATCH(F45,'A6'!$B$2:$X$2,0)) -> 26 | H45: =IF(OR(G45="..",G45="-",$C$10=0),"",G45/$C$10) -> 0.032218092
...

Sheet A1
A1: Table A1 - Number of households by initial assessment of homelessness circumstances and needs England, April 2024 to March 2025
E2: Total number of households assessed1,2 | G2: Total households assessed as owed a duty | H2: Threatened with homelessness - Prevention duty owed | I2: Of which: due to service of valid Section 21 Notice | J2: Homeless - Relief duty owed | L2: Not threatened with homelessness within 56 days - no duty owed | M2: Withdrew application before assessment - no duty owed | N2: Not eligible / no longer eligible - no duty owed
E3: Grand Total | H3: Threatened with homelessness – Prevention Duty owed | I3: Threatened with homelessness due to service of valid Section 21 Notice – Prevention Duty owed | J3: Already homeless – Relief Duty owed (include accepted local connection referrals) | L3: Not threatened with homelessness within 56 days | M3: Withdrew application before assessment - no duty owed | N3: Not eligible / no longer eligible - no duty owed
L4: Number of households
E5: Total initial assessments 1,2,6 | G5: Assessed as owed a duty | L5: Not homeless nor threatened with homelessness within 56 days - no duty owed | M5: Withdrew application before assessment - no duty owed | N5: Not eligible / no longer eligible - no duty owed | P5: Number of households in area5 (000s) | Q5: Households assessed as threatened with homelessness per (000s) | R5: Households assessed as homeless per (000s)
G6: Total owed a prevention or relief duty | H6: Threatened with homelessness within 56 days - Prevention duty owed | I6: Of which: | J6: Homeless - Relief duty owed4
I7: due to service of valid Section 21 Notice3
A8: E92000001 | B8: ENGLAND | E8: 360050 | G8: 330410 | H8: 147870 | I8: 26660 | J8: 182540 | L8: 14060 | M8: 12950 | N8: 2640 | P8: 24367.038 | Q8: 6.0684438 | R8: 7.4912675
A9: E12000007 | B9: London | E9: 77500 | G9: 70740 | H9: 28240 | I9: 4630 | J9: 42500 | L9: 2450 | M9: 3710 | N9: 600 | P9: 3687.399 | Q9: 7.6585149 | R9: 11.525739
A10: - | B10: Rest of England | E10: 282560 | G10: 259670 | H10: 119630 | I10: 22030 | J10: 140040 | L10: 11610 | M10: 9240 | N10: 2040 | P10: 20679.639 | Q10: 5.7849172 | R10: 6.7718784
A12: E12000001 | B12: North East | E12: 20800 | G12: 19720 | H12: 8930 | I12: 1380 | J12: 10780 | L12: 340 | M12: 630 | N12: 120 | P12: 1201.034 | Q12: 7.43526 | R12: 8.9755994
A13: E12000002 | B13: North West | E13: 49230 | G13: 47430 | H13: 20570 | I13: 3970 | J13: 26860 | L13: 1310 | M13: 370 | N13: 110 | P13: 3247.558 | Q13: 6.33399 | R13: 8.27083
A14: E12000003 | B14: Yorkshire and The Humber | E14: 32750 | G14: 31280 | H14: 15100 | I14: 2300 | J14: 16180 | L14: 710 | M14: 470 | N14: 290 | P14: 2393.288 | Q14: 6.3093117 | R14: 6.7605737
A15: E12000004 | B15: East Midlands | E15: 25620 | G15: 24640 | H15: 10800 | I15: 1970 | J15: 13840 | L15: 440 | M15: 270 | N15: 260 | P15: 2125.887 | Q15: 5.0802324 | R15: 6.5102237
A16: E12000005 | B16: West Midlands | E16: 36470 | G16: 31660 | H16: 11810 | I16: 1760 | J16: 19850 | L16: 2710 | M16: 1780 | N16: 320 | P16: 2534.384 | Q16: 4.6599095 | R16: 7.832278
A17: E12000006 | B17: East of England | E17: 36840 | G17: 32630 | H17: 15450 | I17: 2880 | J17: 17170 | L17: 2210 | M17: 1760 | N17: 250 | P17: 2689.206 | Q17: 5.7451902 | R17: 6.3847842
A18: E12000007 | B18: London | E18: 77500 | G18: 70740 | H18: 28240 | I18: 4630 | J18: 42500 | L18: 2450 | M18: 3710 | N18: 600 | P18: 3687.399 | Q18: 7.6585149 | R18: 11.525739
A19: E12000008 | B19: South East | E19: 50270 | G19: 44030 | H19: 23080 | I19: 5310 | J19: 20950 | L19: 3140 | M19: 2620 | N19: 480 | P19: 3936.408 | Q19: 5.8632134 | R19: 5.3221109
A20: E12000009 | B20: South West | E20: 30580 | G20: 28280 | H20: 13880 | I20: 2450 | J20: 14400 | L20: 750 | M20: 1340 | N20: 210 | P20: 2551.874 | Q20: 5.43914 | R20: 5.6429118
... A48: E07000143 | B48: Breckland | E48: 753 | G48: 709 | H48: 199 | I48: 45 | J48: 510 | L48: 25 | M48: 18 | N48: 1 | P48: 63.19 | Q48: 3.1492325 | R48: 8.0708973
A49: E09000005 | B49: Brent | E49: .. | G49: .. | H49: .. | I49: .. | J49: .. | L49: .. | M49: .. | N49: .. | P49: 120.849 | Q49: .. | R49: ..
A50: E07000068 | B50: Brentwood | E50: 206 | G50: 205 | H50: 111 | I50: 22 | J50: 94 | L50: 0 | M50: 1 | N50: 0 | P50: 31.534 | Q50: 3.5200101 | R50: 2.9809095
A51: E06000043 | B51: Brighton & Hove | E51: 1433 | G51: 1387 | H51: 403 | I51: 52 | J51: 984 | L51: 26 | M51: 17 | N51: 3 | P51: 128.635 | Q51: 3.1328954 | R51: 7.6495511
A52: E06000023 | B52: Bristol | E52: 3500 | G52: 3143 | H52: 897 | I52: 80 | J52: 2246 | L52: 173 | M52: 105 | N52: 79 | P52: 202.001 | Q52: 4.4405721 | R52: 11.118757
A53: E07000144 | B53: Broadland | E53: 483 | G53: 469 | H53: 156 | I53: 39 | J53: 313 | L53: 10 | M53: 3 | N53: 1 | P53: 59.498 | Q53: 2.6219369 | R53: 5.260681
A54: E09000006 | B54: Bromley | E54: 1825 | G54: 1661 | H54: 577 | I54: 223 | J54: 1084 | L54: 49 | M54: 115 | N54: 0 | P54: 144.795 | Q54: 3.9849442 | R54: 7.4864464
A55: E07000234 | B55: Bromsgrove | E55: 365 | G55: 355 | H55: 183 | I55: 10 | J55: 172 | L55: 4 | M55: 4 | N55: 2 | P55: 43.48 | Q55: 4.2088316 | R55: 3.9558418
A56: E07000095 | B56: Broxbourne | E56: 644 | G56: 566 | H56: 240 | I56: 31 | J56: 326 | L56: 49 | M56: 27 | N56: 2 | P56: 39.638 | Q56: 6.0547959 | R56: 8.2244311
A57: E07000172 | B57: Broxtowe | E57: 269 | G57: 247 | H57: 133 | I57: 62 | J57: 114 | L57: 6 | M57: 12 | N57: 4 | P57: 50.665 | Q57: 2.6250864 | R57: 2.250074
A58: E06000060 | B58: Buckinghamshire | E58: 4221 | G58: 2518 | H58: 1777 | I58: 150 | J58: 741 | L58: 1100 | M58: 533 | N58: 70 | P58: 224.112 | Q58: 7.9290712 | R58: 3.3063825
A59: E07000117 | B59: Burnley | E59: 689 | G59: 687 | H59: 292 | I59: 86 | J59: 395 | L59: 0 | M59: 0 | N59: 2 | P59: 39.214 | Q59: 7.4463202 | R59: 10.072933
A60: E08000002 | B60: Bury | E60: .. | G60: .. | H60: .. | I60: .. | J60: .. | L60: .. | M60: .. | N60: .. | P60: 83.748 | Q60: .. | R60: ..
A61: E08000033 | B61: Calderdale | E61: 1253 | G61: 1227 | H61: 887 | I61: 84 | J61: 340 | L61: 17 | M61: 3 | N61: 6 | P61: 96.054 | Q61: 9.234389 | R61: 3.5396756
A62: E07000008 | B62: Cambridge | E62: 1073 | G62: 772 | H62: 285 | I62: 27 | J62: 487 | L62: 205 | M62: 77 | N62: 19 | P62: 43.742 | Q62: 6.5154771 | R62: 11.133464
A63: E09000007 | B63: Camden | E63: .. | G63: .. | H63: .. | I63: .. | J63: .. | L63: .. | M63: .. | N63: .. | P63: 120.624 | Q63: .. | R63: ..
A64: E07000192 | B64: Cannock Chase | E64: 171 | G64: 171 | H64: 65 | I64: 4 | J64: 106 | L64: 0 | M64: 0 | N64: 0 | P64: 46.059 | Q64: 1.4112334 | R64: 2.301396
A65: E07000106 | B65: Canterbury | E65: .. | G65: .. | H65: .. | I65: .. | J65: .. | L65: .. | M65: .. | N65: .. | P65: 69.303 | Q65: .. | R65: ..
A66: E07000069 | B66: Castle Point | E66: 261 | G66: 259 | H66: 130 | I66: 73 | J66: 129 | L66: 2 | M66: 0 | N66: 0 | P66: 37.969 | Q66: 3.4238458 | R66: 3.3975085
A67: E06000056 | B67: Central Bedfordshire | E67: 1267 | G67: 1133 | H67: 560 | I67: 94 | J67: 573 | L67: 54 | M67: 76 | N67: 4 | P67: 126.152 | Q67: 4.4390894 | R67: 4.5421396
A68: E07000130 | B68: Charnwood | E68: 638 | G68: 625 | H68: 199 | I68: 41 | J68: 426 | L68: 9 | M68: 4 | N68: 0 | P68: 79.371 | Q68: 2.507213 | R68: 5.3671996
...

Sheet A2P
A1: Table A2P - Number of households owed a prevention duty by reason for loss, or threat of loss, of last settled home England, April 2024 to March 2025
G2: End of private rented tenancy - assured shorthold | AA2: End of private rented tenancy - not assured shorthold | AB2: Family or friends no longer willing or able to accommodate | AC2: Non-violent relationship breakdown with partner | AE2: Domestic abuse | AJ2: Other violence or harrassment | AL2: End of social rented tenancy | AQ2: Eviction from supported housing | AV2: Left institution with no accommodation available | BC2: Required to leave accommodation provided by Home Office as asylum support | BD2: Home no longer suitable - disability / ill health | BF2: Other reasons / not known6
BF3: Number of households
E4: Total owed a prevention duty1 | G4: End of assured shorthold (AST) private rented tenancy, due to: | AA4: End of non-AST private rented tenancy | AB4: Family or friends no longer willing or able to accommodate | AC4: Non-violent relationship breakdown with partner | AE4: Domestic abuse | AJ4: Other violence or harrassment | AL4: End of social rented tenancy, due to: | AQ4: Eviction from supported housing, due to: | AV4: Departure from institution : | BC4: Required to leave accommodation provided by Home Office as asylum support | BD4: Home no longer suitable - disability / ill health 6 | BE4: Loss of placement or sponsorship provided through a resettlement scheme | BF4: Other reasons / not known5
G5: Total end of AST | I5: Of which: | Q5: Landlord wishing to sell or re-let the property | AE5: Total Domestic abuse | AF5: Of which: | AL5: Total end of social rented tenancy | AM5: Of which: | AQ5: Total evicted from supported housing | AR5: Of which: | AV5: Total Departure from institution | AW5: Of which:
I6: Rent arrears, due to: | R6: Of which:
I7: Tenant difficulty budgeting or making other payment(s) | J7: Increase | K7: Reduction in employment income | L7: Changes | M7: Change in personal circumstances | O7: Breach of tenancy, not related to rent arrears | Q7: Total Landlord wishing to sell or re-let the property | R7: sell the property | S7: re-let the property | T7: Retired "Landlord wishing to" option | V7: Tenant complained to the council / agent / landlord about disrepair | W7: Illegal eviction | X7: Tenant abandoned property | Y7: Other reasons / not known | AF7: Victim | AG7: Alleged perpetrator | AH7: Retired "Domestic abuse" option | AM7: Rent arrears2 | AN7: Breach of tenancy, not related to rent arrears | AO7: Other reasons / not known3 | AR7: Rent arrears | AS7: Breach of tenancy or licence, not related to rent arrears | AT7: Other reasons / not known4 | AW7: Custody | AX7: Hospital (psychiatric) | AY7: Hospital (general) | AZ7: Looked After Child Placement | BA7: Retired "Left institution" option
J8: in rent | L8: in benefit entitlement | S8: re-let the property | T8: Retired "Landlord wishing to" option
A9: E92000001 | B9: ENGLAND | E9: 147870 | G9: 57190 | I9: 2370 | J9: 1370 | K9: 940 | L9: 860 | M9: 2500 | O9: 810 | Q9: 37000 | R9: 26440 | S9: 10490 | T9: 70 | V9: 760 | W9: 280 | X9: 290 | Y9: 10020 | AA9: 6010 | AB9: 34980 | AC9: 5890 | AE9: 10610 | AF9: 9990 | AG9: 610 | AH9: 0 | AJ9: 1630 | AL9: 7350 | AM9: 5060 | AN9: 560 | AO9: 1720 | AQ9: 5550 | AR9: 670 | AS9: 1490 | AT9: 3390 | AV9: 4510 | AW9: 3100 | AX9: 240 | AY9: 180 | AZ9: 980 | BA9: 0 | BC9: 4920 | BD9: 2310 | BE9: 800 | BF9: 6110
A10: E12000007 | B10: London | E10: 28240 | G10: 12670 | I10: 430 | J10: 490 | K10: 150 | L10: 510 | M10: 380 | O10: 120 | Q10: 7640 | R10: 4130 | S10: 3450 | T10: 50 | V10: 160 | W10: 70 | X10: 30 | Y10: 2680 | AA10: 1310 | AB10: 6950 | AC10: 410 | AE10: 1240 | AF10: 1170 | AG10: 70 | AH10: 0 | AJ10: 330 | AL10: 1700 | AM10: 1410 | AN10: 40 | AO10: 250 | AQ10: 800 | AR10: 80 | AS10: 100 | AT10: 620 | AV10: 490 | AW10: 320 | AX10: 30 | AY10: 40 | AZ10: 100 | BA10: 0 | BC10: 450 | BD10: 710 | BE10: 90 | BF10: 1090
A11: - | B11: Rest of England | E11: 119630 | G11: 44520 | I11: 1940 | J11: 880 | K11: 780 | L11: 350 | M11: 2120 | O11: 690 | Q11: 29360 | R11: 22300 | S11: 7040 | T11: 20 | V11: 600 | W11: 210 | X11: 260 | Y11: 7340 | AA11: 4700 | AB11: 28040 | AC11: 5480 | AE11: 9370 | AF11: 8820 | AG11: 540 | AH11: 0 | AJ11: 1300 | AL11: 5650 | AM11: 3650 | AN11: 520 | AO11: 1470 | AQ11: 4750 | AR11: 590 | AS11: 1390 | AT11: 2770 | AV11: 4020 | AW11: 2780 | AX11: 220 | AY11: 140 | AZ11: 880 | BA11: 0 | BC11: 4470 | BD11: 1600 | BE11: 720 | BF11: 5020
A13: E12000001 | B13: North East | E13: 8930 | G13: 2890 | I13: 170 | J13: 40 | K13: 20 | L13: 10 | M13: 110 | O13: 40 | Q13: 1930 | R13: 1590 | S13: 340 | T13: 0 | V13: 30 | W13: 30 | X13: 20 | Y13: 500 | AA13: 170 | AB13: 2010 | AC13: 540 | AE13: 880 | AF13: 850 | AG13: 30 | AH13: 0 | AJ13: 190 | AL13: 410 | AM13: 220 | AN13: 50 | AO13: 140 | AQ13: 360 | AR13: 30 | AS13: 100 | AT13: 230 | AV13: 430 | AW13: 350 | AX13: 40 | AY13: 10 | AZ13: 30 | BA13: 0 | BC13: 470 | BD13: 80 | BE13: 20 | BF13: 490
A14: E12000002 | B14: North West | E14: 20570 | G14: 7980 | I14: 300 | J14: 200 | K14: 80 | L14: 50 | M14: 390 | O14: 110 | Q14: 5360 | R14: 4330 | S14: 1030 | T14: 0 | V14: 120 | W14: 30 | X14: 30 | Y14: 1310 | AA14: 740 | AB14: 4340 | AC14: 860 | AE14: 1770 | AF14: 1690 | AG14: 90 | AH14: 0 | AJ14: 150 | AL14: 1000 | AM14: 770 | AN14: 80 | AO14: 160 | AQ14: 480 | AR14: 50 | AS14: 150 | AT14: 290 | AV14: 850 | AW14: 580 | AX14: 40 | AY14: 30 | AZ14: 200 | BA14: 0 | BC14: 1220 | BD14: 260 | BE14: 50 | BF14: 860
A15: E12000003 | B15: Yorkshire and The Humber | E15: 15100 | G15: 4490 | I15: 270 | J15: 80 | K15: 100 | L15: 50 | M15: 240 | O15: 90 | Q15: 2730 | R15: 2200 | S15: 510 | T15: 20 | V15: 110 | W15: 30 | X15: 60 | Y15: 740 | AA15: 430 | AB15: 4240 | AC15: 730 | AE15: 1820 | AF15: 1730 | AG15: 90 | AH15: 0 | AJ15: 200 | AL15: 390 | AM15: 140 | AN15: 50 | AO15: 200 | AQ15: 660 | AR15: 50 | AS15: 190 | AT15: 420 | AV15: 700 | AW15: 590 | AX15: 20 | AY15: 20 | AZ15: 70 | BA15: 0 | BC15: 760 | BD15: 170 | BE15: 10 | BF15: 490
A16: E12000004 | B16: East Midlands | E16: 10800 | G16: 4760 | I16: 240 | J16: 90 | K16: 100 | L16: 40 | M16: 220 | O16: 70 | Q16: 3060 | R16: 2460 | S16: 600 | T16: 0 | V16: 80 | W16: 20 | X16: 30 | Y16: 830 | AA16: 270 | AB16: 2380 | AC16: 490 | AE16: 680 | AF16: 640 | AG16: 40 | AH16: 0 | AJ16: 100 | AL16: 410 | AM16: 210 | AN16: 40 | AO16: 160 | AQ16: 570 | AR16: 60 | AS16: 140 | AT16: 370 | AV16: 200 | AW16: 150 | AX16: 10 | AY16: 0 | AZ16: 30 | BA16: 0 | BC16: 470 | BD16: 100 | BE16: 40 | BF16: 320
A17: E12000005 | B17: West Midlands | E17: 11810 | G17: 3990 | I17: 100 | J17: 90 | K17: 70 | L17: 30 | M17: 190 | O17: 30 | Q17: 2580 | R17: 2050 | S17: 530 | T17: 0 | V17: 60 | W17: 20 | X17: 20 | Y17: 800 | AA17: 550 | AB17: 2800 | AC17: 430 | AE17: 880 | AF17: 840 | AG17: 40 | AH17: 0 | AJ17: 170 | AL17: 660 | AM17: 430 | AN17: 60 | AO17: 170 | AQ17: 780 | AR17: 70 | AS17: 270 | AT17: 430 | AV17: 430 | AW17: 180 | AX17: 20 | AY17: 30 | AZ17: 200 | BA17: 0 | BC17: 430 | BD17: 150 | BE17: 60 | BF17: 480
A18: E12000006 | B18: East of England | E18: 15450 | G18: 5790 | I18: 240 | J18: 110 | K18: 110 | L18: 40 | M18: 260 | O18: 70 | Q18: 4000 | R18: 3040 | S18: 960 | T18: 0 | V18: 60 | W18: 20 | X18: 20 | Y18: 870 | AA18: 730 | AB18: 3680 | AC18: 710 | AE18: 1120 | AF18: 1040 | AG18: 80 | AH18: 0 | AJ18: 170 | AL18: 1020 | AM18: 720 | AN18: 70 | AO18: 230 | AQ18: 600 | AR18: 80 | AS18: 110 | AT18: 410 | AV18: 410 | AW18: 260 | AX18: 20 | AY18: 20 | AZ18: 120 | BA18: 0 | BC18: 310 | BD18: 270 | BE18: 90 | BF18: 540
A19: E12000007 | B19: London | E19: 28240 | G19: 12670 | I19: 430 | J19: 490 | K19: 150 | L19: 510 | M19: 380 | O19: 120 | Q19: 7640 | R19: 4130 | S19: 3450 | T19: 50 | V19: 160 | W19: 70 | X19: 30 | Y19: 2680 | AA19: 1310 | AB19: 6950 | AC19: 410 | AE19: 1240 | AF19: 1170 | AG19: 70 | AH19: 0 | AJ19: 330 | AL19: 1700 | AM19: 1410 | AN19: 40 | AO19: 250 | AQ19: 800 | AR19: 80 | AS19: 100 | AT19: 620 | AV19: 490 | AW19: 320 | AX19: 30 | AY19: 40 | AZ19: 100 | BA19: 0 | BC19: 450 | BD19: 710 | BE19: 90 | BF19: 1090
A20: E12000008 | B20: South East | E20: 23080 | G20: 9210 | I20: 460 | J20: 190 | K20: 210 | L20: 90 | M20: 490 | O20: 180 | Q20: 5980 | R20: 3830 | S20: 2140 | T20: 0 | V20: 100 | W20: 30 | X20: 50 | Y20: 1430 | AA20: 1160 | AB20: 5500 | AC20: 1090 | AE20: 1240 | AF20: 1130 | AG20: 110 | AH20: 0 | AJ20: 220 | AL20: 1090 | AM20: 770 | AN20: 110 | AO20: 220 | AQ20: 740 | AR20: 150 | AS20: 210 | AT20: 380 | AV20: 540 | AW20: 380 | AX20: 30 | AY20: 20 | AZ20: 110 | BA20: 0 | BC20: 520 | BD20: 360 | BE20: 270 | BF20: 1140
A21: E12000009 | B21: South West | E21: 13880 | G21: 5410 | I21: 170 | J21: 70 | K21: 90 | L21: 40 | M21: 220 | O21: 100 | Q21: 3720 | R21: 2790 | S21: 930 | T21: 0 | V21: 60 | W21: 30 | X21: 30 | Y21: 880 | AA21: 650 | AB21: 3080 | AC21: 620 | AE21: 980 | AF21: 910 | AG21: 70 | AH21: 0 | AJ21: 100 | AL21: 650 | AM21: 390 | AN21: 60 | AO21: 200 | AQ21: 560 | AR21: 100 | AS21: 220 | AT21: 250 | AV21: 440 | AW21: 270 | AX21: 30 | AY21: 20 | AZ21: 120 | BA21: 0 | BC21: 290 | BD21: 200 | BE21: 170 | BF21: 700
... A49: E07000143 | B49: Breckland | E49: 199 | G49: 91 | I49: 4 | J49: 0 | K49: 0 | L49: 1 | M49: 2 | O49: 2 | Q49: 70 | R49: 60 | S49: 10 | T49: 0 | V49: 0 | W49: 0 | X49: 2 | Y49: 10 | AA49: 1 | AB49: 43 | AC49: 5 | AE49: 12 | AF49: 11 | AG49: 1 | AH49: 0 | AJ49: 1 | AL49: 8 | AM49: 8 | AN49: 0 | AO49: 0 | AQ49: 8 | AR49: 2 | AS49: 5 | AT49: 1 | AV49: 3 | AW49: 3 | AX49: 0 | AY49: 0 | AZ49: 0 | BA49: 0 | BC49: 0 | BD49: 12 | BE49: 5 | BF49: 10
A50: E09000005 | B50: Brent | E50: .. | G50: .. | I50: .. | J50: .. | K50: .. | L50: .. | M50: .. | O50: .. | Q50: .. | R50: .. | S50: .. | T50: .. | V50: .. | W50: .. | X50: .. | Y50: .. | AA50: .. | AB50: .. | AC50: .. | AE50: .. | AF50: .. | AG50: .. | AH50: .. | AJ50: .. | AL50: .. | AM50: .. | AN50: .. | AO50: .. | AQ50: .. | AR50: .. | AS50: .. | AT50: .. | AV50: .. | AW50: .. | AX50: .. | AY50: .. | AZ50: .. | BA50: .. | BC50: .. | BD50: .. | BE50: .. | BF50: ..
A51: E07000068 | B51: Brentwood | E51: 111 | G51: 49 | I51: 0 | J51: 0 | K51: 0 | L51: 0 | M51: 3 | O51: 0 | Q51: 41 | R51: 28 | S51: 13 | T51: 0 | V51: 1 | W51: 0 | X51: 0 | Y51: 4 | AA51: 13 | AB51: 20 | AC51: 7 | AE51: 8 | AF51: 6 | AG51: 2 | AH51: 0 | AJ51: 0 | AL51: 1 | AM51: 1 | AN51: 0 | AO51: 0 | AQ51: 2 | AR51: 0 | AS51: 0 | AT51: 2 | AV51: 2 | AW51: 2 | AX51: 0 | AY51: 0 | AZ51: 0 | BA51: 0 | BC51: 0 | BD51: 3 | BE51: 1 | BF51: 5
A52: E06000043 | B52: Brighton & Hove | E52: 403 | G52: 192 | I52: 17 | J52: 19 | K52: 4 | L52: 8 | M52: 5 | O52: 14 | Q52: 90 | R52: 64 | S52: 25 | T52: 1 | V52: 4 | W52: 1 | X52: 0 | Y52: 30 | AA52: 24 | AB52: 51 | AC52: 7 | AE52: 10 | AF52: 10 | AG52: 0 | AH52: 0 | AJ52: 15 | AL52: 5 | AM52: 0 | AN52: 1 | AO52: 4 | AQ52: 32 | AR52: 0 | AS52: 7 | AT52: 25 | AV52: 4 | AW52: 2 | AX52: 0 | AY52: 0 | AZ52: 2 | BA52: 0 | BC52: 24 | BD52: 6 | BE52: 6 | BF52: 27
A53: E06000023 | B53: Bristol | E53: 897 | G53: 290 | I53: 23 | J53: 10 | K53: 2 | L53: 7 | M53: 7 | O53: 5 | Q53: 162 | R53: 117 | S53: 45 | T53: 0 | V53: 4 | W53: 5 | X53: 2 | Y53: 63 | AA53: 34 | AB53: 193 | AC53: 22 | AE53: 33 | AF53: 25 | AG53: 8 | AH53: 0 | AJ53: 8 | AL53: 147 | AM53: 130 | AN53: 6 | AO53: 11 | AQ53: 50 | AR53: 10 | AS53: 28 | AT53: 12 | AV53: 51 | AW53: 47 | AX53: 0 | AY53: 0 | AZ53: 4 | BA53: 0 | BC53: 26 | BD53: 2 | BE53: 2 | BF53: 39
A54: E07000144 | B54: Broadland | E54: 156 | G54: 71 | I54: 0 | J54: 0 | K54: 0 | L54: 0 | M54: 2 | O54: 0 | Q54: 62 | R54: 46 | S54: 16 | T54: 0 | V54: 0 | W54: 0 | X54: 0 | Y54: 7 | AA54: 6 | AB54: 47 | AC54: 10 | AE54: 1 | AF54: 1 | AG54: 0 | AH54: 0 | AJ54: 0 | AL54: 4 | AM54: 2 | AN54: 2 | AO54: 0 | AQ54: 3 | AR54: 0 | AS54: 0 | AT54: 3 | AV54: 10 | AW54: 0 | AX54: 0 | AY54: 0 | AZ54: 10 | BA54: 0 | BC54: 1 | BD54: 0 | BE54: 1 | BF54: 2
A55: E09000006 | B55: Bromley | E55: 577 | G55: 300 | I55: 18 | J55: 6 | K55: 11 | L55: 2 | M55: 5 | O55: 2 | Q55: 213 | R55: 139 | S55: 74 | T55: 0 | V55: 3 | W55: 2 | X55: 1 | Y55: 37 | AA55: 12 | AB55: 163 | AC55: 12 | AE55: 19 | AF55: 19 | AG55: 0 | AH55: 0 | AJ55: 12 | AL55: 25 | AM55: 19 | AN55: 0 | AO55: 6 | AQ55: 2 | AR55: 2 | AS55: 0 | AT55: 0 | AV55: 3 | AW55: 3 | AX55: 0 | AY55: 0 | AZ55: 0 | BA55: 0 | BC55: 0 | BD55: 11 | BE55: 4 | BF55: 14
A56: E07000234 | B56: Bromsgrove | E56: 183 | G56: 37 | I56: 0 | J56: 1 | K56: 1 | L56: 0 | M56: 2 | O56: 0 | Q56: 25 | R56: 21 | S56: 4 | T56: 0 | V56: 1 | W56: 1 | X56: 0 | Y56: 6 | AA56: 17 | AB56: 72 | AC56: 7 | AE56: 24 | AF56: 23 | AG56: 1 | AH56: 0 | AJ56: 4 | AL56: 3 | AM56: 0 | AN56: 1 | AO56: 2 | AQ56: 1 | AR56: 0 | AS56: 0 | AT56: 1 | AV56: 5 | AW56: 2 | AX56: 0 | AY56: 0 | AZ56: 3 | BA56: 0 | BC56: 0 | BD56: 5 | BE56: 0 | BF56: 8
A57: E07000095 | B57: Broxbourne | E57: 240 | G57: 100 | I57: 4 | J57: 5 | K57: 2 | L57: 0 | M57: 1 | O57: 1 | Q57: 65 | R57: 45 | S57: 20 | T57: 0 | V57: 0 | W57: 1 | X57: 0 | Y57: 21 | AA57: 18 | AB57: 63 | AC57: 5 | AE57: 11 | AF57: 10 | AG57: 1 | AH57: 0 | AJ57: 1 | AL57: 12 | AM57: 8 | AN57: 0 | AO57: 4 | AQ57: 2 | AR57: 1 | AS57: 0 | AT57: 1 | AV57: 4 | AW57: 2 | AX57: 1 | AY57: 1 | AZ57: 0 | BA57: 0 | BC57: 8 | BD57: 7 | BE57: 0 | BF57: 9
A58: E07000172 | B58: Broxtowe | E58: 133 | G58: 70 | I58: 1 | J58: 1 | K58: 0 | L58: 0 | M58: 1 | O58: 0 | Q58: 57 | R58: 8 | S58: 49 | T58: 0 | V58: 2 | W58: 1 | X58: 0 | Y58: 7 | AA58: 2 | AB58: 30 | AC58: 6 | AE58: 10 | AF58: 9 | AG58: 1 | AH58: 0 | AJ58: 2 | AL58: 1 | AM58: 0 | AN58: 0 | AO58: 1 | AQ58: 2 | AR58: 0 | AS58: 1 | AT58: 1 | AV58: 1 | AW58: 0 | AX58: 0 | AY58: 0 | AZ58: 1 | BA58: 0 | BC58: 5 | BD58: 0 | BE58: 0 | BF58: 4
A59: E06000060 | B59: Buckinghamshire | E59: 1777 | G59: 564 | I59: 37 | J59: 18 | K59: 17 | L59: 10 | M59: 43 | O59: 5 | Q59: 341 | R59: 238 | S59: 103 | T59: 0 | V59: 5 | W59: 5 | X59: 5 | Y59: 78 | AA59: 100 | AB59: 452 | AC59: 92 | AE59: 119 | AF59: 104 | AG59: 15 | AH59: 0 | AJ59: 32 | AL59: 144 | AM59: 113 | AN59: 13 | AO59: 18 | AQ59: 44 | AR59: 14 | AS59: 12 | AT59: 18 | AV59: 52 | AW59: 42 | AX59: 3 | AY59: 3 | AZ59: 4 | BA59: 0 | BC59: 7 | BD59: 43 | BE59: 17 | BF59: 111
A60: E07000117 | B60: Burnley | E60: 292 | G60: 141 | I60: 10 | J60: 4 | K60: 1 | L60: 2 | M60: 4 | O60: 3 | Q60: 85 | R60: 72 | S60: 13 | T60: 0 | V60: 2 | W60: 0 | X60: 0 | Y60: 30 | AA60: 13 | AB60: 55 | AC60: 13 | AE60: 9 | AF60: 9 | AG60: 0 | AH60: 0 | AJ60: 3 | AL60: 5 | AM60: 0 | AN60: 2 | AO60: 3 | AQ60: 9 | AR60: 0 | AS60: 3 | AT60: 6 | AV60: 1 | AW60: 0 | AX60: 0 | AY60: 0 | AZ60: 1 | BA60: 0 | BC60: 24 | BD60: 3 | BE60: 1 | BF60: 15
A61: E08000002 | B61: Bury | E61: .. | G61: .. | I61: .. | J61: .. | K61: .. | L61: .. | M61: .. | O61: .. | Q61: .. | R61: .. | S61: .. | T61: .. | V61: .. | W61: .. | X61: .. | Y61: .. | AA61: .. | AB61: .. | AC61: .. | AE61: .. | AF61: .. | AG61: .. | AH61: .. | AJ61: .. | AL61: .. | AM61: .. | AN61: .. | AO61: .. | AQ61: .. | AR61: .. | AS61: .. | AT61: .. | AV61: .. | AW61: .. | AX61: .. | AY61: .. | AZ61: .. | BA61: .. | BC61: .. | BD61: .. | BE61: .. | BF61: ..
A62: E08000033 | B62: Calderdale | E62: 887 | G62: 193 | I62: 13 | J62: 2 | K62: 3 | L62: 1 | M62: 12 | O62: 9 | Q62: 118 | R62: 99 | S62: 19 | T62: 0 | V62: 4 | W62: 3 | X62: 5 | Y62: 23 | AA62: 39 | AB62: 224 | AC62: 39 | AE62: 74 | AF62: 65 | AG62: 9 | AH62: 0 | AJ62: 4 | AL62: 19 | AM62: 8 | AN62: 1 | AO62: 10 | AQ62: 36 | AR62: 3 | AS62: 14 | AT62: 19 | AV62: 88 | AW62: 59 | AX62: 1 | AY62: 1 | AZ62: 27 | BA62: 0 | BC62: 70 | BD62: 48 | BE62: 1 | BF62: 52
A63: E07000008 | B63: Cambridge | E63: 285 | G63: 73 | I63: 3 | J63: 1 | K63: 0 | L63: 1 | M63: 4 | O63: 2 | Q63: 42 | R63: 28 | S63: 14 | T63: 0 | V63: 1 | W63: 1 | X63: 0 | Y63: 18 | AA63: 19 | AB63: 81 | AC63: 10 | AE63: 15 | AF63: 14 | AG63: 1 | AH63: 0 | AJ63: 1 | AL63: 22 | AM63: 7 | AN63: 2 | AO63: 13 | AQ63: 16 | AR63: 2 | AS63: 5 | AT63: 9 | AV63: 24 | AW63: 7 | AX63: 1 | AY63: 0 | AZ63: 16 | BA63: 0 | BC63: 0 | BD63: 3 | BE63: 2 | BF63: 19
A64: E09000007 | B64: Camden | E64: .. | G64: .. | I64: .. | J64: .. | K64: .. | L64: .. | M64: .. | O64: .. | Q64: .. | R64: .. | S64: .. | T64: .. | V64: .. | W64: .. | X64: .. | Y64: .. | AA64: .. | AB64: .. | AC64: .. | AE64: .. | AF64: .. | AG64: .. | AH64: .. | AJ64: .. | AL64: .. | AM64: .. | AN64: .. | AO64: .. | AQ64: .. | AR64: .. | AS64: .. | AT64: .. | AV64: .. | AW64: .. | AX64: .. | AY64: .. | AZ64: .. | BA64: .. | BC64: .. | BD64: .. | BE64: .. | BF64: ..
A65: E07000192 | B65: Cannock Chase | E65: 65 | G65: 34 | I65: 0 | J65: 0 | K65: 1 | L65: 0 | M65: 1 | O65: 0 | Q65: 29 | R65: 27 | S65: 2 | T65: 0 | V65: 0 | W65: 0 | X65: 0 | Y65: 3 | AA65: 3 | AB65: 16 | AC65: 2 | AE65: 4 | AF65: 4 | AG65: 0 | AH65: 0 | AJ65: 0 | AL65: 2 | AM65: 1 | AN65: 0 | AO65: 1 | AQ65: 1 | AR65: 0 | AS65: 0 | AT65: 1 | AV65: 1 | AW65: 1 | AX65: 0 | AY65: 0 | AZ65: 0 | BA65: 0 | BC65: 1 | BD65: 1 | BE65: 0 | BF65: 0
A66: E07000106 | B66: Canterbury | E66: .. | G66: .. | I66: .. | J66: .. | K66: .. | L66: .. | M66: .. | O66: .. | Q66: .. | R66: .. | S66: .. | T66: .. | V66: .. | W66: .. | X66: .. | Y66: .. | AA66: .. | AB66: .. | AC66: .. | AE66: .. | AF66: .. | AG66: .. | AH66: .. | AJ66: .. | AL66: .. | AM66: .. | AN66: .. | AO66: .. | AQ66: .. | AR66: .. | AS66: .. | AT66: .. | AV66: .. | AW66: .. | AX66: .. | AY66: .. | AZ66: .. | BA66: .. | BC66: .. | BD66: .. | BE66: .. | BF66: ..
A67: E07000069 | B67: Castle Point | E67: 130 | G67: 89 | I67: 3 | J67: 0 | K67: 2 | L67: 0 | M67: 2 | O67: 0 | Q67: 71 | R67: 67 | S67: 4 | T67: 0 | V67: 0 | W67: 0 | X67: 1 | Y67: 10 | AA67: 0 | AB67: 26 | AC67: 3 | AE67: 6 | AF67: 4 | AG67: 2 | AH67: 0 | AJ67: 0 | AL67: 1 | AM67: 1 | AN67: 0 | AO67: 0 | AQ67: 0 | AR67: 0 | AS67: 0 | AT67: 0 | AV67: 0 | AW67: 0 | AX67: 0 | AY67: 0 | AZ67: 0 | BA67: 0 | BC67: 0 | BD67: 2 | BE67: 0 | BF67: 3
A68: E06000056 | B68: Central Bedfordshire | E68: 560 | G68: 196 | I68: 6 | J68: 3 | K68: 5 | L68: 1 | M68: 8 | O68: 0 | Q68: 149 | R68: 120 | S68: 29 | T68: 0 | V68: 1 | W68: 0 | X68: 0 | Y68: 23 | AA68: 37 | AB68: 120 | AC68: 50 | AE68: 88 | AF68: 81 | AG68: 7 | AH68: 0 | AJ68: 6 | AL68: 16 | AM68: 6 | AN68: 1 | AO68: 9 | AQ68: 7 | AR68: 0 | AS68: 0 | AT68: 7 | AV68: 3 | AW68: 1 | AX68: 0 | AY68: 0 | AZ68: 2 | BA68: 0 | BC68: 4 | BD68: 13 | BE68: 3 | BF68: 17
...

Sheet A2R
A1: Table A2R - Number of households owed a relief duty by reason for loss, or threat of loss, of last settled home England, April 2024 to March 2025
G2: End of private rented tenancy - assured shorthold | AA2: End of private rented tenancy - not assured shorthold | AB2: Family or friends no longer willing or able to accommodate | AC2: Non-violent relationship breakdown with partner | AE2: Domestic abuse | AJ2: Other violence or harrassment | AL2: End of social rented tenancy | AQ2: Eviction from supported housing | AV2: Left institution with no accommodation available | BC2: Required to leave accommodation provided by Home Office as asylum support | BE2: Home no longer suitable - disability / ill health | BF2: Other reasons / not known6
BF3: Number of households
E4: Total owed a relief duty1 | G4: End of assured shorthold (AST) private rented tenancy, due to: | AA4: End of non-AST private rented tenancy | AB4: Family or friends no longer willing or able to accommodate | AC4: Non-violent relationship breakdown with partner | AE4: Domestic abuse | AJ4: Other violence or harrassment | AL4: End of social rented tenancy, due to: | AQ4: Eviction from supported housing, due to: | AV4: Departure from institution : | BC4: Required to leave accommodation provided by Home Office as asylum support | BD4: Home no longer suitable - disability / ill health 6 | BE4: Loss of placement or sponsorship provided through a resettlement scheme | BF4: Other reasons / not known5
G5: Total end of AST | I5: Of which: | Q5: Landlord wishing to sell or re-let the property | AE5: Total Domestic abuse | AF5: Of which: | AL5: Total end of social rented tenancy | AM5: Of which: | AQ5: Total evicted from supported housing | AR5: Of which: | AV5: Total Departure from institution | AW5: Of which:
I6: Rent arrears, due to: | R6: Of which:
I7: Tenant difficulty budgeting or making other payment(s) | J7: Increase | K7: Reduction in employment income | L7: Changes | M7: Change in personal circumstances | O7: Breach of tenancy, not related to rent arrears | Q7: Total Landlord wishing to sell or re-let the property | R7: sell the property | S7: re-let the property | T7: Retired "Landlord wishing to" option | V7: Tenant complained to the council / agent / landlord about disrepair | W7: Illegal eviction | X7: Tenant abandoned property | Y7: Other reasons / not known | AF7: Victim | AG7: Alleged perpetrator | AH7: Retired "Domestic abuse" option | AM7: Rent arrears2 | AN7: Breach of tenancy, not related to rent arrears | AO7: Other reasons / not known3 | AR7: Rent arrears | AS7: Breach of tenancy or licence, not related to rent arrears | AT7: Other reasons / not known4 | AW7: Custody | AX7: Hospital (psychiatric) | AY7: Hospital (general) | AZ7: Looked After Child Placement | BA7: Retired "Left institution" option
J8: in rent | L8: in benefit entitlement | S8: re-let the property | T8: Retired "Landlord wishing to" option
A9: E92000001 | B9: ENGLAND | E9: 182540 | G9: 22230 | I9: 1440 | J9: 520 | K9: 590 | L9: 350 | M9: 1610 | O9: 800 | Q9: 8520 | R9: 5540 | S9: 2950 | T9: 30 | V9: 280 | W9: 880 | X9: 1240 | Y9: 6000 | AA9: 5310 | AB9: 54300 | AC9: 12070 | AE9: 28800 | AF9: 25990 | AG9: 2790 | AH9: 10 | AJ9: 5130 | AL9: 4950 | AM9: 1520 | AN9: 1090 | AO9: 2330 | AQ9: 11450 | AR9: 1020 | AS9: 6180 | AT9: 4250 | AV9: 10860 | AW9: 7910 | AX9: 1020 | AY9: 1020 | AZ9: 910 | BA9: 0 | BC9: 13630 | BD9: 2210 | BE9: 360 | BF9: 11260
A10: E12000007 | B10: London | E10: 42500 | G10: 7230 | I10: 370 | J10: 230 | K10: 150 | L10: 180 | M10: 370 | O10: 170 | Q10: 3210 | R10: 1820 | S10: 1370 | T10: 30 | V10: 90 | W10: 240 | X10: 160 | Y10: 2050 | AA10: 1530 | AB10: 13520 | AC10: 1110 | AE10: 5700 | AF10: 5370 | AG10: 330 | AH10: 10 | AJ10: 1210 | AL10: 800 | AM10: 280 | AN10: 130 | AO10: 380 | AQ10: 1780 | AR10: 220 | AS10: 460 | AT10: 1090 | AV10: 2020 | AW10: 1300 | AX10: 310 | AY10: 310 | AZ10: 110 | BA10: 0 | BC10: 4670 | BD10: 700 | BE10: 50 | BF10: 2190
A11: - | B11: Rest of England | E11: 140040 | G11: 14990 | I11: 1070 | J11: 280 | K11: 430 | L11: 170 | M11: 1240 | O11: 630 | Q11: 5310 | R11: 3720 | S11: 1580 | T11: 0 | V11: 190 | W11: 640 | X11: 1080 | Y11: 3940 | AA11: 3790 | AB11: 40790 | AC11: 10960 | AE11: 23100 | AF11: 20620 | AG11: 2470 | AH11: 10 | AJ11: 3920 | AL11: 4150 | AM11: 1240 | AN11: 960 | AO11: 1950 | AQ11: 9670 | AR11: 790 | AS11: 5720 | AT11: 3160 | AV11: 8840 | AW11: 6610 | AX11: 710 | AY11: 710 | AZ11: 800 | BA11: 0 | BC11: 8950 | BD11: 1500 | BE11: 310 | BF11: 9070
A13: E12000001 | B13: North East | E13: 10780 | G13: 1030 | I13: 110 | J13: 10 | K13: 20 | L13: 0 | M13: 70 | O13: 70 | Q13: 320 | R13: 260 | S13: 60 | T13: 0 | V13: 20 | W13: 80 | X13: 70 | Y13: 250 | AA13: 140 | AB13: 3410 | AC13: 1020 | AE13: 1500 | AF13: 1350 | AG13: 150 | AH13: 0 | AJ13: 380 | AL13: 420 | AM13: 150 | AN13: 100 | AO13: 170 | AQ13: 830 | AR13: 60 | AS13: 510 | AT13: 260 | AV13: 690 | AW13: 570 | AX13: 50 | AY13: 50 | AZ13: 20 | BA13: 0 | BC13: 690 | BD13: 40 | BE13: 20 | BF13: 610
A14: E12000002 | B14: North West | E14: 26860 | G14: 2740 | I14: 160 | J14: 70 | K14: 50 | L14: 20 | M14: 220 | O14: 120 | Q14: 920 | R14: 640 | S14: 280 | T14: 0 | V14: 40 | W14: 110 | X14: 290 | Y14: 730 | AA14: 610 | AB14: 8150 | AC14: 1940 | AE14: 3460 | AF14: 2980 | AG14: 490 | AH14: 0 | AJ14: 590 | AL14: 720 | AM14: 220 | AN14: 150 | AO14: 340 | AQ14: 1370 | AR14: 110 | AS14: 820 | AT14: 430 | AV14: 2290 | AW14: 1850 | AX14: 160 | AY14: 170 | AZ14: 110 | BA14: 0 | BC14: 2980 | BD14: 220 | BE14: 40 | BF14: 1740
A15: E12000003 | B15: Yorkshire and The Humber | E15: 16180 | G15: 1660 | I15: 150 | J15: 40 | K15: 60 | L15: 30 | M15: 110 | O15: 60 | Q15: 530 | R15: 370 | S15: 160 | T15: 0 | V15: 30 | W15: 100 | X15: 180 | Y15: 380 | AA15: 250 | AB15: 4500 | AC15: 1210 | AE15: 2940 | AF15: 2670 | AG15: 270 | AH15: 10 | AJ15: 510 | AL15: 480 | AM15: 120 | AN15: 80 | AO15: 280 | AQ15: 1310 | AR15: 80 | AS15: 770 | AT15: 470 | AV15: 1160 | AW15: 1010 | AX15: 50 | AY15: 60 | AZ15: 30 | BA15: 0 | BC15: 1180 | BD15: 150 | BE15: 10 | BF15: 820
A16: E12000004 | B16: East Midlands | E16: 13840 | G16: 1510 | I16: 150 | J16: 30 | K16: 70 | L16: 20 | M16: 110 | O16: 60 | Q16: 430 | R16: 310 | S16: 120 | T16: 0 | V16: 20 | W16: 60 | X16: 100 | Y16: 460 | AA16: 310 | AB16: 4030 | AC16: 1160 | AE16: 2530 | AF16: 2300 | AG16: 220 | AH16: 0 | AJ16: 400 | AL16: 510 | AM16: 140 | AN16: 100 | AO16: 260 | AQ16: 1040 | AR16: 100 | AS16: 570 | AT16: 370 | AV16: 650 | AW16: 470 | AX16: 60 | AY16: 60 | AZ16: 50 | BA16: 0 | BC16: 780 | BD16: 130 | BE16: 20 | BF16: 770
A17: E12000005 | B17: West Midlands | E17: 19850 | G17: 2220 | I17: 100 | J17: 50 | K17: 50 | L17: 30 | M17: 170 | O17: 60 | Q17: 950 | R17: 680 | S17: 270 | T17: 0 | V17: 30 | W17: 80 | X17: 80 | Y17: 640 | AA17: 530 | AB17: 6010 | AC17: 1540 | AE17: 3270 | AF17: 3030 | AG17: 230 | AH17: 0 | AJ17: 500 | AL17: 580 | AM17: 150 | AN17: 150 | AO17: 270 | AQ17: 1520 | AR17: 100 | AS17: 770 | AT17: 650 | AV17: 1000 | AW17: 600 | AX17: 100 | AY17: 130 | AZ17: 170 | BA17: 0 | BC17: 1300 | BD17: 200 | BE17: 60 | BF17: 1110
A18: E12000006 | B18: East of England | E18: 17170 | G18: 1850 | I18: 160 | J18: 40 | K18: 70 | L18: 20 | M18: 170 | O18: 80 | Q18: 720 | R18: 520 | S18: 200 | T18: 0 | V18: 30 | W18: 50 | X18: 100 | Y18: 420 | AA18: 630 | AB18: 4870 | AC18: 1360 | AE18: 3160 | AF18: 2870 | AG18: 290 | AH18: 0 | AJ18: 510 | AL18: 520 | AM18: 170 | AN18: 140 | AO18: 210 | AQ18: 1110 | AR18: 130 | AS18: 660 | AT18: 320 | AV18: 990 | AW18: 680 | AX18: 100 | AY18: 60 | AZ18: 150 | BA18: 0 | BC18: 810 | BD18: 310 | BE18: 40 | BF18: 1020
A19: E12000007 | B19: London | E19: 42500 | G19: 7230 | I19: 370 | J19: 230 | K19: 150 | L19: 180 | M19: 370 | O19: 170 | Q19: 3210 | R19: 1820 | S19: 1370 | T19: 30 | V19: 90 | W19: 240 | X19: 160 | Y19: 2050 | AA19: 1530 | AB19: 13520 | AC19: 1110 | AE19: 5700 | AF19: 5370 | AG19: 330 | AH19: 10 | AJ19: 1210 | AL19: 800 | AM19: 280 | AN19: 130 | AO19: 380 | AQ19: 1780 | AR19: 220 | AS19: 460 | AT19: 1090 | AV19: 2020 | AW19: 1300 | AX19: 310 | AY19: 310 | AZ19: 110 | BA19: 0 | BC19: 4670 | BD19: 700 | BE19: 50 | BF19: 2190
A20: E12000008 | B20: South East | E20: 20950 | G20: 2360 | I20: 170 | J20: 40 | K20: 80 | L20: 30 | M20: 240 | O20: 100 | Q20: 860 | R20: 530 | S20: 330 | T20: 0 | V20: 20 | W20: 90 | X20: 150 | Y20: 600 | AA20: 770 | AB20: 5960 | AC20: 1550 | AE20: 3860 | AF20: 3350 | AG20: 520 | AH20: 0 | AJ20: 670 | AL20: 530 | AM20: 190 | AN20: 130 | AO20: 210 | AQ20: 1110 | AR20: 120 | AS20: 670 | AT20: 320 | AV20: 1190 | AW20: 820 | AX20: 100 | AY20: 100 | AZ20: 180 | BA20: 0 | BC20: 720 | BD20: 280 | BE20: 70 | BF20: 1880
A21: E12000009 | B21: South West | E21: 14400 | G21: 1610 | I21: 80 | J21: 20 | K21: 40 | L21: 10 | M21: 140 | O21: 80 | Q21: 570 | R21: 410 | S21: 160 | T21: 0 | V21: 20 | W21: 60 | X21: 120 | Y21: 470 | AA21: 550 | AB21: 3860 | AC21: 1180 | AE21: 2380 | AF21: 2080 | AG21: 300 | AH21: 0 | AJ21: 360 | AL21: 400 | AM21: 100 | AN21: 100 | AO21: 200 | AQ21: 1380 | AR21: 100 | AS21: 950 | AT21: 330 | AV21: 860 | AW21: 610 | AX21: 90 | AY21: 70 | AZ21: 90 | BA21: 0 | BC21: 490 | BD21: 180 | BE21: 40 | BF21: 1120
... A49: E07000143 | B49: Breckland | E49: 510 | G49: 43 | I49: 2 | J49: 0 | K49: 1 | L49: 0 | M49: 8 | O49: 0 | Q49: 19 | R49: 15 | S49: 4 | T49: 0 | V49: 1 | W49: 1 | X49: 1 | Y49: 10 | AA49: 15 | AB49: 104 | AC49: 37 | AE49: 156 | AF49: 144 | AG49: 12 | AH49: 0 | AJ49: 17 | AL49: 12 | AM49: 2 | AN49: 3 | AO49: 7 | AQ49: 16 | AR49: 3 | AS49: 10 | AT49: 3 | AV49: 28 | AW49: 23 | AX49: 0 | AY49: 2 | AZ49: 3 | BA49: 0 | BC49: 0 | BD49: 56 | BE49: 2 | BF49: 24
A50: E09000005 | B50: Brent | E50: .. | G50: .. | I50: .. | J50: .. | K50: .. | L50: .. | M50: .. | O50: .. | Q50: .. | R50: .. | S50: .. | T50: .. | V50: .. | W50: .. | X50: .. | Y50: .. | AA50: .. | AB50: .. | AC50: .. | AE50: .. | AF50: .. | AG50: .. | AH50: .. | AJ50: .. | AL50: .. | AM50: .. | AN50: .. | AO50: .. | AQ50: .. | AR50: .. | AS50: .. | AT50: .. | AV50: .. | AW50: .. | AX50: .. | AY50: .. | AZ50: .. | BA50: .. | BC50: .. | BD50: .. | BE50: .. | BF50: ..
A51: E07000068 | B51: Brentwood | E51: 94 | G51: 16 | I51: 2 | J51: 0 | K51: 1 | L51: 0 | M51: 2 | O51: 0 | Q51: 7 | R51: 7 | S51: 0 | T51: 0 | V51: 0 | W51: 0 | X51: 1 | Y51: 3 | AA51: 5 | AB51: 23 | AC51: 10 | AE51: 19 | AF51: 17 | AG51: 2 | AH51: 0 | AJ51: 2 | AL51: 4 | AM51: 2 | AN51: 0 | AO51: 2 | AQ51: 1 | AR51: 0 | AS51: 1 | AT51: 0 | AV51: 4 | AW51: 4 | AX51: 0 | AY51: 0 | AZ51: 0 | BA51: 0 | BC51: 0 | BD51: 2 | BE51: 0 | BF51: 8
A52: E06000043 | B52: Brighton & Hove | E52: 984 | G52: 109 | I52: 10 | J52: 5 | K52: 3 | L52: 1 | M52: 7 | O52: 4 | Q52: 30 | R52: 19 | S52: 11 | T52: 0 | V52: 1 | W52: 3 | X52: 3 | Y52: 42 | AA52: 50 | AB52: 222 | AC52: 48 | AE52: 145 | AF52: 131 | AG52: 14 | AH52: 0 | AJ52: 61 | AL52: 14 | AM52: 4 | AN52: 5 | AO52: 5 | AQ52: 95 | AR52: 4 | AS52: 59 | AT52: 32 | AV52: 49 | AW52: 39 | AX52: 6 | AY52: 2 | AZ52: 2 | BA52: 0 | BC52: 39 | BD52: 12 | BE52: 4 | BF52: 136
A53: E06000023 | B53: Bristol | E53: 2246 | G53: 296 | I53: 10 | J53: 6 | K53: 9 | L53: 0 | M53: 16 | O53: 8 | Q53: 112 | R53: 77 | S53: 35 | T53: 0 | V53: 3 | W53: 16 | X53: 17 | Y53: 99 | AA53: 66 | AB53: 708 | AC53: 102 | AE53: 320 | AF53: 298 | AG53: 22 | AH53: 0 | AJ53: 75 | AL53: 46 | AM53: 11 | AN53: 4 | AO53: 31 | AQ53: 166 | AR53: 11 | AS53: 109 | AT53: 46 | AV53: 99 | AW53: 77 | AX53: 3 | AY53: 5 | AZ53: 14 | BA53: 0 | BC53: 160 | BD53: 11 | BE53: 5 | BF53: 192
A54: E07000144 | B54: Broadland | E54: 313 | G54: 22 | I54: 1 | J54: 0 | K54: 1 | L54: 0 | M54: 1 | O54: 0 | Q54: 12 | R54: 6 | S54: 6 | T54: 0 | V54: 1 | W54: 1 | X54: 0 | Y54: 5 | AA54: 8 | AB54: 60 | AC54: 23 | AE54: 115 | AF54: 111 | AG54: 4 | AH54: 0 | AJ54: 10 | AL54: 9 | AM54: 1 | AN54: 3 | AO54: 5 | AQ54: 15 | AR54: 3 | AS54: 11 | AT54: 1 | AV54: 16 | AW54: 2 | AX54: 1 | AY54: 2 | AZ54: 11 | BA54: 0 | BC54: 10 | BD54: 10 | BE54: 0 | BF54: 15
A55: E09000006 | B55: Bromley | E55: 1084 | G55: 160 | I55: 15 | J55: 4 | K55: 6 | L55: 5 | M55: 8 | O55: 5 | Q55: 79 | R55: 54 | S55: 25 | T55: 0 | V55: 6 | W55: 4 | X55: 2 | Y55: 26 | AA55: 29 | AB55: 342 | AC55: 50 | AE55: 227 | AF55: 216 | AG55: 11 | AH55: 0 | AJ55: 93 | AL55: 32 | AM55: 17 | AN55: 3 | AO55: 12 | AQ55: 21 | AR55: 6 | AS55: 6 | AT55: 9 | AV55: 28 | AW55: 24 | AX55: 3 | AY55: 0 | AZ55: 1 | BA55: 0 | BC55: 39 | BD55: 10 | BE55: 0 | BF55: 53
A56: E07000234 | B56: Bromsgrove | E56: 172 | G56: 8 | I56: 0 | J56: 0 | K56: 0 | L56: 0 | M56: 0 | O56: 0 | Q56: 7 | R56: 4 | S56: 3 | T56: 0 | V56: 0 | W56: 0 | X56: 0 | Y56: 1 | AA56: 3 | AB56: 56 | AC56: 15 | AE56: 62 | AF56: 61 | AG56: 1 | AH56: 0 | AJ56: 3 | AL56: 5 | AM56: 0 | AN56: 4 | AO56: 1 | AQ56: 3 | AR56: 0 | AS56: 2 | AT56: 1 | AV56: 10 | AW56: 4 | AX56: 0 | AY56: 0 | AZ56: 6 | BA56: 0 | BC56: 0 | BD56: 3 | BE56: 0 | BF56: 4
A57: E07000095 | B57: Broxbourne | E57: 326 | G57: 23 | I57: 0 | J57: 1 | K57: 1 | L57: 0 | M57: 1 | O57: 0 | Q57: 15 | R57: 14 | S57: 1 | T57: 0 | V57: 0 | W57: 0 | X57: 0 | Y57: 5 | AA57: 8 | AB57: 114 | AC57: 20 | AE57: 46 | AF57: 42 | AG57: 4 | AH57: 0 | AJ57: 10 | AL57: 1 | AM57: 0 | AN57: 0 | AO57: 1 | AQ57: 6 | AR57: 0 | AS57: 4 | AT57: 2 | AV57: 25 | AW57: 11 | AX57: 6 | AY57: 3 | AZ57: 5 | BA57: 0 | BC57: 48 | BD57: 10 | BE57: 0 | BF57: 15
A58: E07000172 | B58: Broxtowe | E58: 114 | G58: 19 | I58: 2 | J58: 1 | K58: 0 | L58: 0 | M58: 3 | O58: 2 | Q58: 5 | R58: 0 | S58: 5 | T58: 0 | V58: 0 | W58: 0 | X58: 0 | Y58: 6 | AA58: 1 | AB58: 30 | AC58: 10 | AE58: 22 | AF58: 19 | AG58: 3 | AH58: 0 | AJ58: 2 | AL58: 4 | AM58: 0 | AN58: 1 | AO58: 3 | AQ58: 7 | AR58: 0 | AS58: 4 | AT58: 3 | AV58: 4 | AW58: 2 | AX58: 0 | AY58: 1 | AZ58: 1 | BA58: 0 | BC58: 6 | BD58: 1 | BE58: 0 | BF58: 8
A59: E06000060 | B59: Buckinghamshire | E59: 741 | G59: 54 | I59: 3 | J59: 1 | K59: 0 | L59: 0 | M59: 9 | O59: 2 | Q59: 18 | R59: 9 | S59: 9 | T59: 0 | V59: 2 | W59: 4 | X59: 6 | Y59: 9 | AA59: 29 | AB59: 226 | AC59: 43 | AE59: 126 | AF59: 106 | AG59: 20 | AH59: 0 | AJ59: 29 | AL59: 22 | AM59: 9 | AN59: 8 | AO59: 5 | AQ59: 47 | AR59: 12 | AS59: 25 | AT59: 10 | AV59: 71 | AW59: 53 | AX59: 8 | AY59: 8 | AZ59: 2 | BA59: 0 | BC59: 11 | BD59: 12 | BE59: 2 | BF59: 69
A60: E07000117 | B60: Burnley | E60: 395 | G60: 25 | I60: 7 | J60: 2 | K60: 0 | L60: 0 | M60: 1 | O60: 1 | Q60: 7 | R60: 6 | S60: 1 | T60: 0 | V60: 0 | W60: 0 | X60: 3 | Y60: 4 | AA60: 8 | AB60: 128 | AC60: 59 | AE60: 26 | AF60: 21 | AG60: 5 | AH60: 0 | AJ60: 2 | AL60: 10 | AM60: 1 | AN60: 5 | AO60: 4 | AQ60: 22 | AR60: 1 | AS60: 14 | AT60: 7 | AV60: 46 | AW60: 39 | AX60: 2 | AY60: 4 | AZ60: 1 | BA60: 0 | BC60: 47 | BD60: 3 | BE60: 1 | BF60: 18
A61: E08000002 | B61: Bury | E61: .. | G61: .. | I61: .. | J61: .. | K61: .. | L61: .. | M61: .. | O61: .. | Q61: .. | R61: .. | S61: .. | T61: .. | V61: .. | W61: .. | X61: .. | Y61: .. | AA61: .. | AB61: .. | AC61: .. | AE61: .. | AF61: .. | AG61: .. | AH61: .. | AJ61: .. | AL61: .. | AM61: .. | AN61: .. | AO61: .. | AQ61: .. | AR61: .. | AS61: .. | AT61: .. | AV61: .. | AW61: .. | AX61: .. | AY61: .. | AZ61: .. | BA61: .. | BC61: .. | BD61: .. | BE61: .. | BF61: ..
A62: E08000033 | B62: Calderdale | E62: 340 | G62: 32 | I62: 1 | J62: 0 | K62: 1 | L62: 0 | M62: 3 | O62: 5 | Q62: 7 | R62: 3 | S62: 4 | T62: 0 | V62: 1 | W62: 4 | X62: 6 | Y62: 4 | AA62: 12 | AB62: 89 | AC62: 22 | AE62: 73 | AF62: 73 | AG62: 0 | AH62: 0 | AJ62: 14 | AL62: 7 | AM62: 3 | AN62: 1 | AO62: 3 | AQ62: 13 | AR62: 0 | AS62: 11 | AT62: 2 | AV62: 25 | AW62: 21 | AX62: 2 | AY62: 2 | AZ62: 0 | BA62: 0 | BC62: 25 | BD62: 5 | BE62: 0 | BF62: 23
A63: E07000008 | B63: Cambridge | E63: 487 | G63: 32 | I63: 5 | J63: 0 | K63: 1 | L63: 0 | M63: 2 | O63: 0 | Q63: 15 | R63: 8 | S63: 7 | T63: 0 | V63: 2 | W63: 0 | X63: 1 | Y63: 6 | AA63: 17 | AB63: 103 | AC63: 30 | AE63: 95 | AF63: 90 | AG63: 5 | AH63: 0 | AJ63: 19 | AL63: 10 | AM63: 1 | AN63: 4 | AO63: 5 | AQ63: 49 | AR63: 10 | AS63: 34 | AT63: 5 | AV63: 47 | AW63: 38 | AX63: 2 | AY63: 2 | AZ63: 5 | BA63: 0 | BC63: 9 | BD63: 11 | BE63: 1 | BF63: 64
